<?xml version="1.0" encoding="utf-8"?>
<!-- This URDF was automatically created by SolidWorks to URDF Exporter! Originally created by Stephen Brawner (brawner@gmail.com)
     Commit Version: 1.6.0-4-g7f85cfe  Build Version: 1.6.7995.38578
     For more information, please see http://wiki.ros.org/sw_urdf_exporter -->
<robot
  name="x500_arm2x">
  <link
    name="base_link">
    <inertial>
      <origin
        xyz="-0.01095289 0.00014522 -0.06446611"
        rpy="0 0 0" />
      <mass
        value="2.20454277" />
      <inertia
        ixx="0.02478373"
        ixy="5.142E-05"
        ixz="0.00098728"
        iyy="0.02764354"
        iyz="-4.258E-05"
        izz="0.03898878" />
    </inertial>
    <visual>
      <origin
        xyz="0 0 0"
        rpy="0 0 0" />
      <geometry>
        <mesh
          filename="package://x500_arm2x/meshes/base_link.STL" />
      </geometry>
      <material
        name="">
        <color
          rgba="1 1 1 1" />
      </material>
    </visual>
    <collision>
      <origin
        xyz="0 0 0"
        rpy="0 0 0" />
      <geometry>
        <mesh
          filename="package://x500_arm2x/meshes/base_link.STL" />
      </geometry>
    </collision>
  </link>
  <link
    name="link_1">
    <inertial>
      <origin
        xyz="-0.025459 0.17263 -0.00094115"
        rpy="0 0 0" />
      <mass
        value="0.15156" />
      <inertia
        ixx="0.00087586"
        ixy="0.0001761"
        ixz="-2.32E-06"
        iyy="9.027E-05"
        iyz="7.76E-06"
        izz="0.00092044" />
    </inertial>
    <visual>
      <origin
        xyz="0 0 0"
        rpy="0 0 0" />
      <geometry>
        <mesh
          filename="package://x500_arm2x/meshes/link_1.STL" />
      </geometry>
      <material
        name="">
        <color
          rgba="1 1 1 1" />
      </material>
    </visual>
    <collision>
      <origin
        xyz="0 0 0"
        rpy="0 0 0" />
      <geometry>
        <mesh
          filename="package://x500_arm2x/meshes/link_1.STL" />
      </geometry>
    </collision>
  </link>
  <joint
    name="joint_1"
    type="revolute">
    <origin
      xyz="0 0.0002 -0.1503"
      rpy="-1.5708 0 3.1416" />
    <parent
      link="base_link" />
    <child
      link="link_1" />
    <axis
      xyz="0 0 1" />
    <limit
      lower="-2.6485"
      upper="2.6485"
      effort="5.24"
      velocity="6.28" />
  </joint>
  <link
    name="link_2">
    <inertial>
      <origin
        xyz="-0.039172 -0.18259 -0.00068453"
        rpy="0 0 0" />
      <mass
        value="0.14766" />
      <inertia
        ixx="0.0016083"
        ixy="-4.92E-05"
        ixz="-1.8E-07"
        iyy="4.02E-05"
        iyz="-8.08E-06"
        izz="0.0016046" />
    </inertial>
    <visual>
      <origin
        xyz="0 0 0"
        rpy="0 0 0" />
      <geometry>
        <mesh
          filename="package://x500_arm2x/meshes/link_2.STL" />
      </geometry>
      <material
        name="">
        <color
          rgba="1 1 1 1" />
      </material>
    </visual>
    <collision>
      <origin
        xyz="0 0 0"
        rpy="0 0 0" />
      <geometry>
        <mesh
          filename="package://x500_arm2x/meshes/link_2.STL" />
      </geometry>
    </collision>
  </link>
  <joint
    name="joint_2"
    type="revolute">
    <origin
      xyz="-0.04123 0.2314 -0.0005"
      rpy="0 0 3.1416" />
    <parent
      link="link_1" />
    <child
      link="link_2" />
    <axis
      xyz="0 0 1" />
    <limit
      lower="0"
      upper="3.1415"
      effort="3.92"
      velocity="7.85" />
  </joint>
  <link
    name="link_3">
    <inertial>
      <origin
        xyz="0.0055284 -0.033186 -3.76E-06"
        rpy="0 0 0" />
      <mass
        value="0.0636" />
      <inertia
        ixx="2.011E-05"
        ixy="1.71E-06"
        ixz="0"
        iyy="1.802E-05"
        iyz="0"
        izz="2.34E-05" />
    </inertial>
    <visual>
      <origin
        xyz="0 0 0"
        rpy="0 0 0" />
      <geometry>
        <mesh
          filename="package://x500_arm2x/meshes/link_3.STL" />
      </geometry>
      <material
        name="">
        <color
          rgba="1 1 1 1" />
      </material>
    </visual>
    <collision>
      <origin
        xyz="0 0 0"
        rpy="0 0 0" />
      <geometry>
        <mesh
          filename="package://x500_arm2x/meshes/link_3.STL" />
      </geometry>
    </collision>
  </link>
  <joint
    name="joint_3"
    type="revolute">
    <origin
      xyz="-0.04098 -0.2686 0"
      rpy="0 0 0" />
    <parent
      link="link_2" />
    <child
      link="link_3" />
    <axis
      xyz="0 0 1" />
    <limit
      lower="-2.6485"
      upper="2.6485"
      effort="2.75"
      velocity="4.71" />
  </joint>
  <link
    name="link_4">
    <inertial>
      <origin
        xyz="-2.33E-06 -0.00203681 0.03131523"
        rpy="0 0 0" />
      <mass
        value="0.1025" />
      <inertia
        ixx="3.829E-05"
        ixy="0"
        ixz="0"
        iyy="0.00015462"
        iyz="-2.75E-06"
        izz="0.00014456" />
    </inertial>
    <visual>
      <origin
        xyz="0 0 0"
        rpy="0 0 0" />
      <geometry>
        <mesh
          filename="package://x500_arm2x/meshes/link_4.STL" />
      </geometry>
      <material
        name="">
        <color
          rgba="1 1 1 1" />
      </material>
    </visual>
    <collision>
      <origin
        xyz="0 0 0"
        rpy="0 0 0" />
      <geometry>
        <mesh
          filename="package://x500_arm2x/meshes/link_4.STL" />
      </geometry>
    </collision>
  </link>
  <joint
    name="joint_4"
    type="revolute">
    <origin
      xyz="0 -0.05189 0"
      rpy="1.5708 1.5708 0" />
    <parent
      link="link_3" />
    <child
      link="link_4" />
    <axis
      xyz="0 0 1" />
    <limit
      lower="-3.1415"
      upper="3.1415"
      effort="1.11"
      velocity="10.47" />
  </joint>
  <link
    name="link_5">
    <inertial>
      <origin
        xyz="0 0 0.002665"
        rpy="0 0 0" />
      <mass
        value="0.0035" />
      <inertia
        ixx="2.6E-07"
        ixy="2.8E-07"
        ixz="0"
        iyy="7.6E-07"
        iyz="0"
        izz="1E-06" />
    </inertial>
    <visual>
      <origin
        xyz="0 0 0"
        rpy="0 0 0" />
      <geometry>
        <mesh
          filename="package://x500_arm2x/meshes/link_5.STL" />
      </geometry>
      <material
        name="">
        <color
          rgba="1 1 1 1" />
      </material>
    </visual>
    <collision>
      <origin
        xyz="0 0 0"
        rpy="0 0 0" />
      <geometry>
        <mesh
          filename="package://x500_arm2x/meshes/link_5.STL" />
      </geometry>
    </collision>
  </link>
  <joint
    name="joint_5"
    type="revolute">
    <origin
      xyz="0 0 0.037"
      rpy="0 0 0" />
    <parent
      link="link_4" />
    <child
      link="link_5" />
    <axis
      xyz="0 0 1" />
    <limit
      lower="-1.723"
      upper="0"
      effort="1.11"
      velocity="10.47" />
  </joint>
  <link
    name="gripper_left">
    <inertial>
      <origin
        xyz="0.0089947 -0.0050627 0.0083405"
        rpy="0 0 0" />
      <mass
        value="0.02324" />
      <inertia
        ixx="1.266E-05"
        ixy="-2.5E-07"
        ixz="2.7E-07"
        iyy="3.86E-06"
        iyz="-3.5E-07"
        izz="1.48E-05" />
    </inertial>
    <visual>
      <origin
        xyz="0 0 0"
        rpy="0 0 0" />
      <geometry>
        <mesh
          filename="package://x500_arm2x/meshes/gripper_left.STL" />
      </geometry>
      <material
        name="">
        <color
          rgba="1 1 1 1" />
      </material>
    </visual>
    <collision>
      <origin
        xyz="0 0 0"
        rpy="0 0 0" />
      <geometry>
        <mesh
          filename="package://x500_arm2x/meshes/gripper_left.STL" />
      </geometry>
    </collision>
  </link>
  <joint
    name="joint_gripper_left"
    type="prismatic">
    <origin
      xyz="0.040975 0.008255 0.0643"
      rpy="-1.5708 0 -1.5708" />
    <parent
      link="link_4" />
    <child
      link="gripper_left" />
    <axis
      xyz="0 0 1" />
    <limit
      lower="-0.04225"
      upper="0"
      effort="22.7"
      velocity="0.257" />
  </joint>
  <link
    name="gripper_right">
    <inertial>
      <origin
        xyz="-0.0074652 -0.004931 0.0083524"
        rpy="0 0 0" />
      <mass
        value="0.02348" />
      <inertia
        ixx="1.271E-05"
        ixy="-7.6E-07"
        ixz="2.1E-07"
        iyy="3.86E-06"
        iyz="-3.5E-07"
        izz="1.484E-05" />
    </inertial>
    <visual>
      <origin
        xyz="0 0 0"
        rpy="0 0 0" />
      <geometry>
        <mesh
          filename="package://x500_arm2x/meshes/gripper_right.STL" />
      </geometry>
      <material
        name="">
        <color
          rgba="1 1 1 1" />
      </material>
    </visual>
    <collision>
      <origin
        xyz="0 0 0"
        rpy="0 0 0" />
      <geometry>
        <mesh
          filename="package://x500_arm2x/meshes/gripper_right.STL" />
      </geometry>
    </collision>
  </link>
  <joint
    name="joint_gripper_right"
    type="prismatic">
    <origin
      xyz="-0.040975 0.008255 0.0643"
      rpy="-1.5708 0 1.5708" />
    <parent
      link="link_4" />
    <child
      link="gripper_right" />
    <axis
      xyz="0 0 1" />
    <limit
      lower="-0.04225"
      upper="0"
      effort="22.7"
      velocity="0.257" />
  </joint>
  <link
    name="rotor_1">
    <inertial>
      <origin
        xyz="-1.19E-06 0 -0.0005619"
        rpy="0 0 0" />
      <mass
        value="0.0132" />
      <inertia
        ixx="1.251E-05"
        ixy="0"
        ixz="0"
        iyy="1.251E-05"
        iyz="0"
        izz="2.489E-05" />
    </inertial>
    <visual>
      <origin
        xyz="0 0 0"
        rpy="0 0 0" />
      <geometry>
        <mesh
          filename="package://x500_arm2x/meshes/rotor_1.STL" />
      </geometry>
      <material
        name="">
        <color
          rgba="1 1 1 1" />
      </material>
    </visual>
    <collision>
      <origin
        xyz="0 0 0"
        rpy="0 0 0" />
      <geometry>
        <mesh
          filename="package://x500_arm2x/meshes/rotor_1.STL" />
      </geometry>
    </collision>
  </link>
  <joint
    name="joint_rotor_1"
    type="continuous">
    <origin
      xyz="0.17688 -0.17688 0.0086418"
      rpy="0 0 0" />
    <parent
      link="base_link" />
    <child
      link="rotor_1" />
    <axis
      xyz="0 0 1" />
    <limit
      effort="0.18"
      velocity="1032.2" />
  </joint>
  <link
    name="rotor_2">
    <inertial>
      <origin
        xyz="-1.19E-06 0 -0.0005619"
        rpy="0 0 0" />
      <mass
        value="0.0132" />
      <inertia
        ixx="1.251E-05"
        ixy="0"
        ixz="0"
        iyy="1.251E-05"
        iyz="0"
        izz="2.489E-05" />
    </inertial>
    <visual>
      <origin
        xyz="0 0 0"
        rpy="0 0 0" />
      <geometry>
        <mesh
          filename="package://x500_arm2x/meshes/rotor_2.STL" />
      </geometry>
      <material
        name="">
        <color
          rgba="1 1 1 1" />
      </material>
    </visual>
    <collision>
      <origin
        xyz="0 0 0"
        rpy="0 0 0" />
      <geometry>
        <mesh
          filename="package://x500_arm2x/meshes/rotor_2.STL" />
      </geometry>
    </collision>
  </link>
  <joint
    name="joint_rotor_2"
    type="continuous">
    <origin
      xyz="-0.17688 0.17688 0.0086418"
      rpy="0 0 0" />
    <parent
      link="base_link" />
    <child
      link="rotor_2" />
    <axis
      xyz="0 0 1" />
    <limit
      effort="0.18"
      velocity="1032.2" />
  </joint>
  <link
    name="rotor_3">
    <inertial>
      <origin
        xyz="0 -1.31E-06 -0.00056244"
        rpy="0 0 0" />
      <mass
        value="0.0132" />
      <inertia
        ixx="1.251E-05"
        ixy="0"
        ixz="0"
        iyy="1.251E-05"
        iyz="0"
        izz="2.489E-05" />
    </inertial>
    <visual>
      <origin
        xyz="0 0 0"
        rpy="0 0 0" />
      <geometry>
        <mesh
          filename="package://x500_arm2x/meshes/rotor_3.STL" />
      </geometry>
      <material
        name="">
        <color
          rgba="1 1 1 1" />
      </material>
    </visual>
    <collision>
      <origin
        xyz="0 0 0"
        rpy="0 0 0" />
      <geometry>
        <mesh
          filename="package://x500_arm2x/meshes/rotor_3.STL" />
      </geometry>
    </collision>
  </link>
  <joint
    name="joint_rotor_3"
    type="continuous">
    <origin
      xyz="0.17688 0.17688 0.0086418"
      rpy="0 0 0" />
    <parent
      link="base_link" />
    <child
      link="rotor_3" />
    <axis
      xyz="0 0 1" />
    <limit
      effort="0.18"
      velocity="1032.2" />
  </joint>
  <link
    name="rotor_4">
    <inertial>
      <origin
        xyz="0 -1.31E-06 -0.00056244"
        rpy="0 0 0" />
      <mass
        value="0.0132" />
      <inertia
        ixx="1.251E-05"
        ixy="0"
        ixz="0"
        iyy="1.251E-05"
        iyz="0"
        izz="2.489E-05" />
    </inertial>
    <visual>
      <origin
        xyz="0 0 0"
        rpy="0 0 0" />
      <geometry>
        <mesh
          filename="package://x500_arm2x/meshes/rotor_4.STL" />
      </geometry>
      <material
        name="">
        <color
          rgba="1 1 1 1" />
      </material>
    </visual>
    <collision>
      <origin
        xyz="0 0 0"
        rpy="0 0 0" />
      <geometry>
        <mesh
          filename="package://x500_arm2x/meshes/rotor_4.STL" />
      </geometry>
    </collision>
  </link>
  <joint
    name="joint_rotor_4"
    type="continuous">
    <origin
      xyz="-0.17688 -0.17688 0.0086418"
      rpy="0 0 0" />
    <parent
      link="base_link" />
    <child
      link="rotor_4" />
    <axis
      xyz="0 0 1" />
    <limit
      effort="0.18"
      velocity="1032.2" />
  </joint>
</robot>
