<?xml version='1.0' encoding='utf-8'?>
<mujoco model="x500_arm2x">
  <compiler angle="radian" meshdir="meshes/" texturedir="meshes/" />
  <option density="1.225" timestep="0.001" integrator="implicit" viscosity="1.8e-5" cone="elliptic" impratio="10" magnetic="2.73e-5 0 -4.54e-5" />
  <asset>
    <mesh name="base_link" content_type="model/stl" file="base_link.STL" />
    <mesh name="base_link_decomp_0" content_type="model/stl" file="base_link_decomp_0.stl" />
    <mesh name="base_link_decomp_1" content_type="model/stl" file="base_link_decomp_1.stl" />
    <mesh name="base_link_decomp_2" content_type="model/stl" file="base_link_decomp_2.stl" />
    <mesh name="base_link_decomp_3" content_type="model/stl" file="base_link_decomp_3.stl" />
    <mesh name="base_link_decomp_4" content_type="model/stl" file="base_link_decomp_4.stl" />
    <mesh name="base_link_decomp_5" content_type="model/stl" file="base_link_decomp_5.stl" />
    <mesh name="base_link_decomp_6" content_type="model/stl" file="base_link_decomp_6.stl" />
    <mesh name="base_link_decomp_7" content_type="model/stl" file="base_link_decomp_7.stl" />
    <mesh name="base_link_decomp_8" content_type="model/stl" file="base_link_decomp_8.stl" />
    <mesh name="base_link_decomp_9" content_type="model/stl" file="base_link_decomp_9.stl" />
    <mesh name="base_link_decomp_10" content_type="model/stl" file="base_link_decomp_10.stl" />
    <mesh name="base_link_decomp_11" content_type="model/stl" file="base_link_decomp_11.stl" />
    <mesh name="link_1" content_type="model/stl" file="link_1.STL" />
    <mesh name="link_1_decomp_0" content_type="model/stl" file="link_1_decomp_0.stl" />
    <mesh name="link_1_decomp_1" content_type="model/stl" file="link_1_decomp_1.stl" />
    <mesh name="link_2" content_type="model/stl" file="link_2.STL" />
    <mesh name="link_2_decomp_0" content_type="model/stl" file="link_2_decomp_0.stl" />
    <mesh name="link_2_decomp_1" content_type="model/stl" file="link_2_decomp_1.stl" />
    <mesh name="link_3" content_type="model/stl" file="link_3.STL" />
    <mesh name="link_3_decomp_0" content_type="model/stl" file="link_3_decomp_0.stl" />
    <mesh name="link_3_decomp_1" content_type="model/stl" file="link_3_decomp_1.stl" />
    <mesh name="link_3_decomp_2" content_type="model/stl" file="link_3_decomp_2.stl" />
    <mesh name="link_3_decomp_3" content_type="model/stl" file="link_3_decomp_3.stl" />
    <mesh name="link_3_decomp_4" content_type="model/stl" file="link_3_decomp_4.stl" />
    <mesh name="link_3_decomp_5" content_type="model/stl" file="link_3_decomp_5.stl" />
    <mesh name="link_3_decomp_6" content_type="model/stl" file="link_3_decomp_6.stl" />
    <mesh name="link_3_decomp_7" content_type="model/stl" file="link_3_decomp_7.stl" />
    <mesh name="link_3_decomp_8" content_type="model/stl" file="link_3_decomp_8.stl" />
    <mesh name="link_3_decomp_9" content_type="model/stl" file="link_3_decomp_9.stl" />
    <mesh name="link_3_decomp_10" content_type="model/stl" file="link_3_decomp_10.stl" />
    <mesh name="link_3_decomp_11" content_type="model/stl" file="link_3_decomp_11.stl" />
    <mesh name="link_3_decomp_12" content_type="model/stl" file="link_3_decomp_12.stl" />
    <mesh name="link_3_decomp_13" content_type="model/stl" file="link_3_decomp_13.stl" />
    <mesh name="link_4" content_type="model/stl" file="link_4.STL" />
    <mesh name="link_4_decomp_0" content_type="model/stl" file="link_4_decomp_0.stl" />
    <mesh name="link_4_decomp_1" content_type="model/stl" file="link_4_decomp_1.stl" />
    <mesh name="link_4_decomp_2" content_type="model/stl" file="link_4_decomp_2.stl" />
    <mesh name="link_4_decomp_3" content_type="model/stl" file="link_4_decomp_3.stl" />
    <mesh name="link_4_decomp_4" content_type="model/stl" file="link_4_decomp_4.stl" />
    <mesh name="link_4_decomp_5" content_type="model/stl" file="link_4_decomp_5.stl" />
    <mesh name="link_5" content_type="model/stl" file="link_5.STL" />
    <mesh name="link_5_decomp_0" content_type="model/stl" file="link_5_decomp_0.stl" />
    <mesh name="link_5_decomp_1" content_type="model/stl" file="link_5_decomp_1.stl" />
    <mesh name="link_5_decomp_2" content_type="model/stl" file="link_5_decomp_2.stl" />
    <mesh name="link_5_decomp_3" content_type="model/stl" file="link_5_decomp_3.stl" />
    <mesh name="link_5_decomp_4" content_type="model/stl" file="link_5_decomp_4.stl" />
    <mesh name="link_5_decomp_5" content_type="model/stl" file="link_5_decomp_5.stl" />
    <mesh name="gripper_left" content_type="model/stl" file="gripper_left.STL" />
    <mesh name="gripper_left_decomp_0" content_type="model/stl" file="gripper_left_decomp_0.stl" />
    <mesh name="gripper_left_decomp_1" content_type="model/stl" file="gripper_left_decomp_1.stl" />
    <mesh name="gripper_left_decomp_2" content_type="model/stl" file="gripper_left_decomp_2.stl" />
    <mesh name="gripper_right" content_type="model/stl" file="gripper_right.STL" />
    <mesh name="gripper_right_decomp_0" content_type="model/stl" file="gripper_right_decomp_0.stl" />
    <mesh name="gripper_right_decomp_1" content_type="model/stl" file="gripper_right_decomp_1.stl" />
    <mesh name="gripper_right_decomp_2" content_type="model/stl" file="gripper_right_decomp_2.stl" />
    <mesh name="gripper_right_decomp_3" content_type="model/stl" file="gripper_right_decomp_3.stl" />
    <mesh name="rotor_1" content_type="model/stl" file="rotor_1.STL" />
    <mesh name="rotor_1_decomp_0" content_type="model/stl" file="rotor_1_decomp_0.stl" />
    <mesh name="rotor_2" content_type="model/stl" file="rotor_2.STL" />
    <mesh name="rotor_2_decomp_0" content_type="model/stl" file="rotor_2_decomp_0.stl" />
    <mesh name="rotor_3" content_type="model/stl" file="rotor_3.STL" />
    <mesh name="rotor_3_decomp_0" content_type="model/stl" file="rotor_3_decomp_0.stl" />
    <mesh name="rotor_4" content_type="model/stl" file="rotor_4.STL" />
    <mesh name="rotor_4_decomp_0" content_type="model/stl" file="rotor_4_decomp_0.stl" />
  </asset>
  <worldbody>
    <body name="base_link" pos="0 0 0.313075">
      <inertial pos="-0.012812 0.0001697 -0.056763" quat="0.00663375 0.724717 -0.00817561 0.688966" mass="1.9041" diaginertia="0.0434203 0.03019 0.0276677" />
      <joint name="floating_base_joint" type="free" />
      <geom type="mesh" mesh="base_link" density="0" rgba="1 1 1 1" group="1" contype="0" conaffinity="0" />
      <geom type="mesh" mesh="base_link_decomp_0" rgba="1 1 1 1" group="3" contype="1" conaffinity="1" />
      <geom type="mesh" mesh="base_link_decomp_1" rgba="1 1 1 1" group="3" contype="1" conaffinity="1" />
      <geom type="mesh" mesh="base_link_decomp_2" rgba="1 1 1 1" group="3" contype="1" conaffinity="1" />
      <geom type="mesh" mesh="base_link_decomp_3" rgba="1 1 1 1" group="3" contype="1" conaffinity="1" />
      <geom type="mesh" mesh="base_link_decomp_4" rgba="1 1 1 1" group="3" contype="1" conaffinity="1" />
      <geom type="mesh" mesh="base_link_decomp_5" rgba="1 1 1 1" group="3" contype="1" conaffinity="1" />
      <geom type="mesh" mesh="base_link_decomp_6" rgba="1 1 1 1" group="3" contype="1" conaffinity="1" />
      <geom type="mesh" mesh="base_link_decomp_7" rgba="1 1 1 1" group="3" contype="1" conaffinity="1" />
      <geom type="mesh" mesh="base_link_decomp_8" rgba="1 1 1 1" group="3" contype="1" conaffinity="1" />
      <geom type="mesh" mesh="base_link_decomp_9" rgba="1 1 1 1" group="3" contype="1" conaffinity="1" />
      <geom type="mesh" mesh="base_link_decomp_10" rgba="1 1 1 1" group="3" contype="1" conaffinity="1" />
      <geom type="mesh" mesh="base_link_decomp_11" rgba="1 1 1 1" group="3" contype="1" conaffinity="1" />
      <body name="link_1" pos="0 0.0002 -0.1453" quat="-2.59734e-06 2.59735e-06 -0.707108 0.707105">
        <inertial pos="-0.025459 0.17263 -0.00094115" quat="0.421014 0.52647 -0.467095 0.572187" mass="0.15156" diaginertia="0.000920574 0.00091347 5.25261e-05" />
        <joint name="joint_1" pos="0 0 0" axis="0 0 1" range="-2.6485 2.6485" actuatorfrcrange="-5.24 5.24" />
        <geom type="mesh" mesh="link_1" density="0" rgba="1 1 1 1" group="1" contype="0" conaffinity="0" />
        <geom type="mesh" mesh="link_1_decomp_0" rgba="1 1 1 1" group="3" contype="1" conaffinity="1" />
        <geom type="mesh" mesh="link_1_decomp_1" rgba="1 1 1 1" group="3" contype="1" conaffinity="1" />
        <body name="link_2" pos="-0.04098 0.2314 -0.0005" quat="-3.67321e-06 0 0 1">
          <inertial pos="-0.0392 -0.18256 -0.00068407" quat="0.705248 0.708767 -0.0151532 -0.00670206" mass="0.14776" diaginertia="0.0016066 0.00160074 3.49202e-05" />
          <joint name="joint_2" pos="0 0 0" axis="0 0 1" range="0 3.4907" actuatorfrcrange="-3.92 3.92" />
          <geom type="mesh" mesh="link_2" density="0" rgba="1 1 1 1" group="1" contype="0" conaffinity="0" />
          <geom type="mesh" mesh="link_2_decomp_0" rgba="1 1 1 1" group="3" contype="1" conaffinity="1" />
          <geom type="mesh" mesh="link_2_decomp_1" rgba="1 1 1 1" group="3" contype="1" conaffinity="1" />
          <body name="link_3" pos="-0.04098 -0.26861 0">
            <inertial pos="-0.006126 -0.036115 1.5e-06" quat="-0.0787852 0.702704 0.0787852 0.702704" mass="0.062" diaginertia="2.059e-05 1.7423e-05 1.3487e-05" />
            <joint name="joint_3" pos="0 0 0" axis="0 0 1" range="-2.6485 2.6485" actuatorfrcrange="-2.75 2.75" />
            <geom type="mesh" mesh="link_3" density="0" rgba="1 1 1 1" group="1" contype="0" conaffinity="0" />
            <geom type="mesh" mesh="link_3_decomp_0" rgba="1 1 1 1" group="3" contype="1" conaffinity="1" />
            <geom type="mesh" mesh="link_3_decomp_1" rgba="1 1 1 1" group="3" contype="1" conaffinity="1" />
            <geom type="mesh" mesh="link_3_decomp_2" rgba="1 1 1 1" group="3" contype="1" conaffinity="1" />
            <geom type="mesh" mesh="link_3_decomp_3" rgba="1 1 1 1" group="3" contype="1" conaffinity="1" />
            <geom type="mesh" mesh="link_3_decomp_4" rgba="1 1 1 1" group="3" contype="1" conaffinity="1" />
            <geom type="mesh" mesh="link_3_decomp_5" rgba="1 1 1 1" group="3" contype="1" conaffinity="1" />
            <geom type="mesh" mesh="link_3_decomp_6" rgba="1 1 1 1" group="3" contype="1" conaffinity="1" />
            <geom type="mesh" mesh="link_3_decomp_7" rgba="1 1 1 1" group="3" contype="1" conaffinity="1" />
            <geom type="mesh" mesh="link_3_decomp_8" rgba="1 1 1 1" group="3" contype="1" conaffinity="1" />
            <geom type="mesh" mesh="link_3_decomp_9" rgba="1 1 1 1" group="3" contype="1" conaffinity="1" />
            <geom type="mesh" mesh="link_3_decomp_10" rgba="1 1 1 1" group="3" contype="1" conaffinity="1" />
            <geom type="mesh" mesh="link_3_decomp_11" rgba="1 1 1 1" group="3" contype="1" conaffinity="1" />
            <geom type="mesh" mesh="link_3_decomp_12" rgba="1 1 1 1" group="3" contype="1" conaffinity="1" />
            <geom type="mesh" mesh="link_3_decomp_13" rgba="1 1 1 1" group="3" contype="1" conaffinity="1" />
            <body name="link_4" pos="0 -0.05189 0" quat="0.499998 0.5 0.5 -0.500002">
              <inertial pos="-2.05e-06 -0.001772 0.034507" quat="0.537502 0.459447 0.537502 0.459447" mass="0.11656" diaginertia="0.000195533 0.000171857 5.463e-05" />
              <joint name="joint_4" pos="0 0 0" axis="0 0 1" range="-3.1416 3.1416" actuatorfrcrange="-1.11 1.11" />
              <geom type="mesh" mesh="link_4" density="0" rgba="1 1 1 1" group="1" contype="0" conaffinity="0" />
              <geom type="mesh" mesh="link_4_decomp_0" rgba="1 1 1 1" group="3" contype="1" conaffinity="1" />
              <geom type="mesh" mesh="link_4_decomp_1" rgba="1 1 1 1" group="3" contype="1" conaffinity="1" />
              <geom type="mesh" mesh="link_4_decomp_2" rgba="1 1 1 1" group="3" contype="1" conaffinity="1" />
              <geom type="mesh" mesh="link_4_decomp_3" rgba="1 1 1 1" group="3" contype="1" conaffinity="1" />
              <geom type="mesh" mesh="link_4_decomp_4" rgba="1 1 1 1" group="3" contype="1" conaffinity="1" />
              <geom type="mesh" mesh="link_4_decomp_5" rgba="1 1 1 1" group="3" contype="1" conaffinity="1" />
              <body name="link_5" pos="0 0 0.037">
                <inertial pos="0 0 0.002665" quat="0.147739 0.691501 -0.147739 0.691501" mass="0.0035" diaginertia="1e-06 8.85366e-07 1.34634e-07" />
                <joint name="joint_5" pos="0 0 0" axis="0 0 1" range="-1.723 0" actuatorfrcrange="-1.11 1.11" />
                <geom type="mesh" mesh="link_5" density="0" rgba="1 1 1 1" group="1" contype="0" conaffinity="0" />
                <geom type="mesh" mesh="link_5_decomp_0" rgba="1 1 1 1" group="3" contype="1" conaffinity="1" />
                <geom type="mesh" mesh="link_5_decomp_1" rgba="1 1 1 1" group="3" contype="1" conaffinity="1" />
                <geom type="mesh" mesh="link_5_decomp_2" rgba="1 1 1 1" group="3" contype="1" conaffinity="1" />
                <geom type="mesh" mesh="link_5_decomp_3" rgba="1 1 1 1" group="3" contype="1" conaffinity="1" />
                <geom type="mesh" mesh="link_5_decomp_4" rgba="1 1 1 1" group="3" contype="1" conaffinity="1" />
                <geom type="mesh" mesh="link_5_decomp_5" rgba="1 1 1 1" group="3" contype="1" conaffinity="1" />
                <body name="gripper_left" pos="0.04225 0.00825 0.0359" quat="0.499998 -0.5 0.500002 -0.5">
                  <inertial pos="0.0091857 -0.0057172 0.0081891" quat="0.547131 0.528773 -0.475795 0.44121" mass="0.02254" diaginertia="1.48827e-05 1.28562e-05 3.71114e-06" />
                  <joint name="joint_gripper_left" type="slide" pos="0 0 0" axis="0 0 1" range="-0.04225 0" actuatorfrcrange="-49.06 49.06" />
                  <geom type="mesh" mesh="gripper_left" density="0" rgba="1 1 1 1" group="1" contype="0" conaffinity="0" />
                  <geom type="mesh" mesh="gripper_left_decomp_0" rgba="1 1 1 1" group="3" contype="1" conaffinity="1" />
                  <geom type="mesh" mesh="gripper_left_decomp_1" rgba="1 1 1 1" group="3" contype="1" conaffinity="1" />
                  <geom type="mesh" mesh="gripper_left_decomp_2" rgba="1 1 1 1" group="3" contype="1" conaffinity="1" />
                </body>
                <body name="gripper_right" pos="-0.04225 0.00825 0.0359" quat="0.499998 -0.5 -0.500002 0.5">
                  <inertial pos="-0.0071038 -0.009438 0.0079063" quat="0.561645 0.498602 -0.501752 0.429181" mass="0.01854" diaginertia="1.33317e-05 1.14361e-05 3.43212e-06" />
                  <joint name="joint_gripper_right" type="slide" pos="0 0 0" axis="0 0 1" range="-0.04225 0" actuatorfrcrange="-49.06 49.06" />
                  <geom type="mesh" mesh="gripper_right" density="0" rgba="1 1 1 1" group="1" contype="0" conaffinity="0" />
                  <geom type="mesh" mesh="gripper_right_decomp_0" rgba="1 1 1 1" group="3" contype="1" conaffinity="1" />
                  <geom type="mesh" mesh="gripper_right_decomp_1" rgba="1 1 1 1" group="3" contype="1" conaffinity="1" />
                  <geom type="mesh" mesh="gripper_right_decomp_2" rgba="1 1 1 1" group="3" contype="1" conaffinity="1" />
                  <geom type="mesh" mesh="gripper_right_decomp_3" rgba="1 1 1 1" group="3" contype="1" conaffinity="1" />
                </body>
              </body>
            </body>
          </body>
        </body>
      </body>
      <body name="rotor_1" pos="0.17688 -0.17688 0.0153">
        <site name="rotor_joint_thrust1" type="cylinder" size="0.01 0.005" pos="0 0 0" rgba="1 0 0 0.5" />
      </body>
      <body name="rotor_2" pos="-0.17688 0.17688 0.0153">
        <site name="rotor_joint_thrust2" type="cylinder" size="0.01 0.005" pos="0 0 0" rgba="1 0 0 0.5" />
      </body>
      <body name="rotor_3" pos="0.17688 0.17688 0.0153">
        <site name="rotor_joint_thrust3" type="cylinder" size="0.01 0.005" pos="0 0 0" rgba="1 0 0 0.5" />
      </body>
      <body name="rotor_4" pos="-0.17688 -0.17688 0.0153">
        <site name="rotor_joint_thrust4" type="cylinder" size="0.01 0.005" pos="0 0 0" rgba="1 0 0 0.5" />
      </body>
      <site name="base_link_origin" type="sphere" size="0.01" pos="0 0 0" rgba="1 0 0 0.5" />
      <site name="rotor_offset_1" type="sphere" size="0.005" pos="0.176880 -0.176880 0.015300" rgba="0 0 1 0.5" />
      <site name="rotor_offset_2" type="sphere" size="0.005" pos="-0.176880 0.176880 0.015300" rgba="0 0 1 0.5" />
      <site name="rotor_offset_3" type="sphere" size="0.005" pos="0.176880 0.176880 0.015300" rgba="0 0 1 0.5" />
      <site name="rotor_offset_4" type="sphere" size="0.005" pos="-0.176880 -0.176880 0.015300" rgba="0 0 1 0.5" />
    </body>
    <body name="rotor_1_vis" pos="0.17688 -0.17688 0.328375" quat="1 0 0 0" mocap="true">
      <geom type="mesh" mesh="rotor_1" density="0" rgba="1 1 1 1" group="1" contype="0" conaffinity="0" />
    </body>
    <body name="rotor_2_vis" pos="-0.17688 0.17688 0.328375" quat="1 0 0 0" mocap="true">
      <geom type="mesh" mesh="rotor_2" density="0" rgba="1 1 1 1" group="1" contype="0" conaffinity="0" />
    </body>
    <body name="rotor_3_vis" pos="0.17688 0.17688 0.328375" quat="1 0 0 0" mocap="true">
      <geom type="mesh" mesh="rotor_3" density="0" rgba="1 1 1 1" group="1" contype="0" conaffinity="0" />
    </body>
    <body name="rotor_4_vis" pos="-0.17688 -0.17688 0.328375" quat="1 0 0 0" mocap="true">
      <geom type="mesh" mesh="rotor_4" density="0" rgba="1 1 1 1" group="1" contype="0" conaffinity="0" />
    </body>
  </worldbody>
  <sensor>
    <framepos name="framepos" objtype="site" objname="base_link_origin" />
    <framequat name="framequat" objtype="site" objname="base_link_origin" />
    <framelinvel name="framelinvel" objtype="site" objname="base_link_origin" />
    <gyro name="gyro" site="base_link_origin" />
    <accelerometer name="accelerometer" site="base_link_origin" />
    <magnetometer name="magnetometer" site="base_link_origin" />
  </sensor>
  <actuator>
    <position name="joint_1" kp="60.05" kv="3.54" joint="joint_1" forcerange="-5.24 5.24" ctrlrange="-2.6485 2.6485" />
    <position name="joint_2" kp="44.95" kv="1.75" joint="joint_2" forcerange="-3.92 3.92" ctrlrange="0 3.4907" />
    <position name="joint_3" kp="31.47" kv="0.58" joint="joint_3" forcerange="-2.75 2.75" ctrlrange="-2.6485 2.6485" />
    <position name="joint_4" kp="12.77" kv="0.106" joint="joint_4" forcerange="-1.11 1.11" ctrlrange="-3.1416 3.1416" />
    <position name="joint_5" kp="12.77" kv="0.106" joint="joint_5" forcerange="-1.11 1.11" ctrlrange="-1.723 0" />
    <position name="joint_gripper_left" kp="10600.0" kv="88.6" joint="joint_gripper_left" forcerange="-22.7 22.7" ctrlrange="-0.04225 0" />
    <position name="joint_gripper_right" kp="10600.0" kv="88.6" joint="joint_gripper_right" forcerange="-22.7 22.7" ctrlrange="-0.04225 0" />
  </actuator>
  <keyframe>
    <key name="home" qpos="0 0 0.31307474143667563 1 0 0 0 -1.5708 3.1416 0.0 0.0 0.0 0 0" />
  </keyframe>
  <contact>
    <exclude body1="base_link" body2="link_1" />
    <exclude body1="link_1" body2="link_2" />
    <exclude body1="link_2" body2="link_3" />
    <exclude body1="link_3" body2="link_4" />
    <exclude body1="link_4" body2="link_5" />
    <exclude body1="link_5" body2="gripper_left" />
    <exclude body1="link_5" body2="gripper_right" />
    <exclude body1="gripper_right" body2="gripper_left" />
    <exclude body1="base_link" body2="rotor_1" />
    <exclude body1="rotor_1" body2="link_1" />
    <exclude body1="base_link" body2="rotor_2" />
    <exclude body1="rotor_2" body2="link_1" />
    <exclude body1="rotor_2" body2="rotor_1" />
    <exclude body1="base_link" body2="rotor_3" />
    <exclude body1="rotor_3" body2="link_1" />
    <exclude body1="rotor_3" body2="rotor_1" />
    <exclude body1="rotor_3" body2="rotor_2" />
    <exclude body1="base_link" body2="rotor_4" />
    <exclude body1="rotor_4" body2="link_1" />
    <exclude body1="rotor_4" body2="rotor_1" />
    <exclude body1="rotor_4" body2="rotor_2" />
    <exclude body1="rotor_4" body2="rotor_3" />
  </contact>
</mujoco>
