<?xml version='1.0' encoding='utf-8'?>
<mujoco model="plane">
  <compiler angle="radian" meshdir="meshes/" texturedir="meshes/" />
  <option density="1.225" timestep="0.001" integrator="implicit" viscosity="1.8e-5" cone="elliptic" impratio="10" magnetic="2.73e-5 0 -4.54e-5" />
  <size njmax="500" nconmax="100" />
  <asset>
    <mesh name="base_link_visual_0" file="base_link_visual_0.stl" />
    <mesh name="rotor_4_vis" file="rotor_4_vis.stl" />
    <mesh name="left_elevon_visual_0" file="left_elevon_visual_0.stl" />
    <mesh name="right_elevon_visual_0" file="right_elevon_visual_0.stl" />
    <mesh name="left_flap_visual_0" file="left_flap_visual_0.stl" />
    <mesh name="right_flap_visual_0" file="right_flap_visual_0.stl" />
    <mesh name="elevator_visual_0" file="elevator_visual_0.stl" />
    <mesh name="rudder_visual_0" file="rudder_visual_0.stl" />
  </asset>
  <worldbody>
    <body name="base_link" pos="0 0 0.175">
      <inertial pos="0 0 0" quat="0.707107 0.707107 0 0" mass="1" diaginertia="0.197563 0.1477 0.145893" />
      <joint name="floating_base_joint" type="free" />
      <geom type="mesh" mesh="base_link_visual_0" pos="0.07 0 -0.08" rgba="0.175 0.175 0.175 1" group="1" contype="0" conaffinity="0" />
      <geom type="box" size="0.235 0.235 0.055" pos="0 0 -0.07" rgba="0 0 0 0" group="3" contype="1" conaffinity="1" />
      <body name="rotor_4" pos="0.3 0 0">
        <geom type="cylinder" size="0.1 0.0025" rgba="0 0 0 0" group="3" contype="1" conaffinity="1" />
        <site name="rotor_joint_thrust4" type="cylinder" size="0.01 0.005" pos="0 0 -0.09" rgba="1 0 0 0.5" />
      </body>
      <body name="left_elevon" pos="-0.07 0.4 0.08">
        <inertial pos="0 0.3 0" mass="1e-08" diaginertia="1e-06 1e-06 1e-06" />
        <joint name="left_elevon_joint" pos="0 0 0" axis="0 1 0" limited="true" range="-0.78 0.78" damping="1" />
        <geom type="mesh" mesh="left_elevon_visual_0" pos="0.07 0 -0.08" rgba="1 0 0 1" group="1" contype="0" conaffinity="0" />
      </body>
      <body name="right_elevon" pos="-0.07 -0.4 0.08">
        <inertial pos="0 -0.3 0" mass="1e-08" diaginertia="1e-06 1e-06 1e-06" />
        <joint name="right_elevon_joint" pos="0 0 0" axis="0 1 0" limited="true" range="-0.78 0.78" damping="1" />
        <geom type="mesh" mesh="right_elevon_visual_0" pos="0.07 0 -0.08" rgba="1 0 0 1" group="1" contype="0" conaffinity="0" />
      </body>
      <body name="left_flap" pos="-0.07 0.2 0.08">
        <inertial pos="0 0.15 0" mass="1e-08" diaginertia="1e-06 1e-06 1e-06" />
        <joint name="left_flap_joint" pos="0 0 0" axis="0 1 0" limited="true" range="-0.78 0.78" damping="1" />
        <geom type="mesh" mesh="left_flap_visual_0" pos="0.07 0 -0.08" rgba="1 0 0 1" group="1" contype="0" conaffinity="0" />
      </body>
      <body name="right_flap" pos="-0.07 -0.2 0.08">
        <inertial pos="0 -0.15 0" mass="1e-08" diaginertia="1e-06 1e-06 1e-06" />
        <joint name="right_flap_joint" pos="0 0 0" axis="0 1 0" limited="true" range="-0.78 0.78" damping="1" />
        <geom type="mesh" mesh="right_flap_visual_0" pos="0.07 0 -0.08" rgba="1 0 0 1" group="1" contype="0" conaffinity="0" />
      </body>
      <body name="elevator" pos="-0.5 0 0">
        <inertial pos="-0.5 0 0" mass="1e-08" diaginertia="1e-06 1e-06 1e-06" />
        <joint name="elevator_joint" pos="0 0 0" axis="0 1 0" limited="true" range="-0.78 0.78" damping="1" />
        <geom type="mesh" mesh="elevator_visual_0" pos="0.07 0 -0.08" rgba="1 0 0 1" group="1" contype="0" conaffinity="0" />
      </body>
      <body name="rudder" pos="-0.5 0 0.05">
        <inertial pos="-0.5 0 0.05" mass="1e-08" diaginertia="1e-06 1e-06 1e-06" />
        <joint name="rudder_joint" pos="0 0 0" axis="0 0 1" limited="true" range="-0.78 0.78" damping="1" />
        <geom type="mesh" mesh="rudder_visual_0" pos="0.07 0 -0.08" rgba="1 0 0 1" group="1" contype="0" conaffinity="0" />
      </body>
      <site name="base_link_origin" type="sphere" size="0.01" pos="0 0 0" rgba="1 0 0 0.5" />
      <site name="rotor_offset_4" type="sphere" size="0.005" pos="0.300000 0.000000 -0.090000" rgba="0 0 1 0.5" />
    </body>
    <body name="rotor_4_vis" pos="0.3 0 0.085" quat="1 0 0 0" mocap="true">
      <geom type="mesh" mesh="rotor_4_vis" quat="0.707107 0 0.707107 0" rgba="0.175 0.175 0.175 1" group="1" contype="0" conaffinity="0" />
    </body>
  </worldbody>
  <sensor>
    <framepos name="framepos" objtype="site" objname="base_link_origin" />
    <framequat name="framequat" objtype="site" objname="base_link_origin" />
    <framelinvel name="framelinvel" objtype="site" objname="base_link_origin" />
    <gyro name="gyro" site="base_link_origin" />
    <accelerometer name="accelerometer" site="base_link_origin" />
    <magnetometer name="magnetometer" site="base_link_origin" />
  </sensor>
  <actuator>
    <position name="rudder_ctrl" kp="40" joint="rudder_joint" ctrlrange="-0.78 0.78" ctrllimited="true" />
    <position name="left_flap_ctrl" kp="40" joint="left_flap_joint" ctrlrange="-0.78 0.78" ctrllimited="true" />
    <position name="right_flap_ctrl" kp="40" joint="right_flap_joint" ctrlrange="-0.78 0.78" ctrllimited="true" />
    <position name="left_elevon_ctrl" kp="40" joint="left_elevon_joint" ctrlrange="-0.78 0.78" ctrllimited="true" />
    <position name="right_elevon_ctrl" kp="40" joint="right_elevon_joint" ctrlrange="-0.78 0.78" ctrllimited="true" />
    <position name="elevator_ctrl" kp="40" joint="elevator_joint" ctrlrange="-0.78 0.78" ctrllimited="true" />
  </actuator>
  <keyframe>
    <key name="home" qpos="0 0 0.175 1 0 0 0 0 0 0 0 0 0" />
  </keyframe>
  <contact>
    <exclude body1="base_link" body2="rotor_4" />
    <exclude body1="base_link" body2="left_elevon" />
    <exclude body1="left_elevon" body2="rotor_4" />
    <exclude body1="base_link" body2="right_elevon" />
    <exclude body1="right_elevon" body2="rotor_4" />
    <exclude body1="right_elevon" body2="left_elevon" />
    <exclude body1="base_link" body2="left_flap" />
    <exclude body1="left_flap" body2="rotor_4" />
    <exclude body1="left_flap" body2="left_elevon" />
    <exclude body1="left_flap" body2="right_elevon" />
    <exclude body1="base_link" body2="right_flap" />
    <exclude body1="right_flap" body2="rotor_4" />
    <exclude body1="right_flap" body2="left_elevon" />
    <exclude body1="right_flap" body2="right_elevon" />
    <exclude body1="right_flap" body2="left_flap" />
    <exclude body1="base_link" body2="elevator" />
    <exclude body1="elevator" body2="rotor_4" />
    <exclude body1="elevator" body2="left_elevon" />
    <exclude body1="elevator" body2="right_elevon" />
    <exclude body1="elevator" body2="left_flap" />
    <exclude body1="elevator" body2="right_flap" />
    <exclude body1="base_link" body2="rudder" />
    <exclude body1="rudder" body2="rotor_4" />
    <exclude body1="rudder" body2="left_elevon" />
    <exclude body1="rudder" body2="right_elevon" />
    <exclude body1="rudder" body2="left_flap" />
    <exclude body1="rudder" body2="right_flap" />
    <exclude body1="rudder" body2="elevator" />
  </contact>
</mujoco>
