<?xml version="1.0" encoding="utf-8"?>
<robot name="iris">
  <link name="base_link">
    <inertial>
      <origin xyz="0 0 0" rpy="0 0 0" />
      <mass value="1.5" />
      <inertia ixx="0.029125" ixy="0" ixz="0" iyy="0.029125" iyz="0" izz="0.055225" />
    </inertial>
    <visual>
      <origin xyz="0 0 0" rpy="0 0 0" />
      <geometry>
        <mesh filename="package://iris/meshes/iris.stl" />
      </geometry>
    </visual>
    <collision>
      <origin xyz="0 0 0" rpy="0 0 0" />
      <geometry>
        <box size="0.47 0.47 0.11" />
      </geometry>
    </collision>
  </link>

  <link name="rotor_1">
    <inertial>
      <origin xyz="0 0 0" rpy="0 0 0" />
      <mass value="0.005" />
      <inertia ixx="9.75e-07" ixy="0" ixz="0" iyy="0.000273104" iyz="0" izz="0.000274004" />
    </inertial>
    <visual>
      <origin xyz="0 0 0" rpy="0 0 0" />
      <geometry>
        <mesh filename="package://iris/meshes/iris_prop_ccw.stl" />
      </geometry>
    </visual>
    <collision>
      <origin xyz="0 0 0" rpy="0 0 0" />
      <geometry>
        <cylinder radius="0.128" length="0.005" />
      </geometry>
    </collision>
  </link>
  <joint name="rotor_joint_1" type="continuous">
    <origin xyz="0.13 -0.22 0.023" rpy="0 0 0" />
    <parent link="base_link" />
    <child link="rotor_1" />
    <axis xyz="0 0 1" />
    <limit effort="0.2" velocity="1100.0" />
  </joint>

  <link name="rotor_2">
    <inertial>
      <origin xyz="0 0 0" rpy="0 0 0" />
      <mass value="0.005" />
      <inertia ixx="9.75e-07" ixy="0" ixz="0" iyy="0.000273104" iyz="0" izz="0.000274004" />
    </inertial>
    <visual>
      <origin xyz="0 0 0" rpy="0 0 0" />
      <geometry>
        <mesh filename="package://iris/meshes/iris_prop_ccw.stl" />
      </geometry>
    </visual>
    <collision>
      <origin xyz="0 0 0" rpy="0 0 0" />
      <geometry>
        <cylinder radius="0.128" length="0.005" />
      </geometry>
    </collision>
  </link>
  <joint name="rotor_joint_2" type="continuous">
    <origin xyz="-0.13 0.2 0.023" rpy="0 0 0" />
    <parent link="base_link" />
    <child link="rotor_2" />
    <axis xyz="0 0 1" />
    <limit effort="0.2" velocity="1100.0" />
  </joint>

  <link name="rotor_3">
    <inertial>
      <origin xyz="0 0 0" rpy="0 0 0" />
      <mass value="0.005" />
      <inertia ixx="9.75e-07" ixy="0" ixz="0" iyy="0.000273104" iyz="0" izz="0.000274004" />
    </inertial>
    <visual>
      <origin xyz="0 0 0" rpy="0 0 0" />
      <geometry>
        <mesh filename="package://iris/meshes/iris_prop_cw.stl" />
      </geometry>
    </visual>
    <collision>
      <origin xyz="0 0 0" rpy="0 0 0" />
      <geometry>
        <cylinder radius="0.128" length="0.005" />
      </geometry>
    </collision>
  </link>
  <joint name="rotor_joint_3" type="continuous">
    <origin xyz="0.13 0.22 0.023" rpy="0 0 0" />
    <parent link="base_link" />
    <child link="rotor_3" />
    <axis xyz="0 0 1" />
    <limit effort="0.2" velocity="1100.0" />
  </joint>

  <link name="rotor_4">
    <inertial>
      <origin xyz="0 0 0" rpy="0 0 0" />
      <mass value="0.005" />
      <inertia ixx="9.75e-07" ixy="0" ixz="0" iyy="0.000273104" iyz="0" izz="0.000274004" />
    </inertial>
    <visual>
      <origin xyz="0 0 0" rpy="0 0 0" />
      <geometry>
        <mesh filename="package://iris/meshes/iris_prop_cw.stl" />
      </geometry>
    </visual>
    <collision>
      <origin xyz="0 0 0" rpy="0 0 0" />
      <geometry>
        <cylinder radius="0.128" length="0.005" />
      </geometry>
    </collision>
  </link>
  <joint name="rotor_joint_4" type="continuous">
    <origin xyz="-0.13 -0.2 0.023" rpy="0 0 0" />
    <parent link="base_link" />
    <child link="rotor_4" />
    <axis xyz="0 0 1" />
    <limit effort="0.2" velocity="1100.0" />
  </joint>
</robot>
